[2025-02-23 01:16:22,373: INFO : common: yaml file: config/config.yaml loaded successfully]
[2025-02-23 01:16:22,373: INFO : common: yaml file: params.yaml loaded successfully]
[2025-02-23 01:22:05,984: INFO : common: yaml file: config/config.yaml loaded successfully]
[2025-02-23 01:22:05,987: INFO : common: yaml file: params.yaml loaded successfully]
[2025-02-23 01:22:05,988: INFO : common: created directory at artifacts]
[2025-02-23 01:22:05,989: INFO : common: created directory at artifacts/data_ingestion]
[2025-02-23 01:22:05,989: INFO : 2399328493: Downloading data from https://drive.google.com/file/d/1IcEWOO8q8VpidPF4p51wlHPXXUnNONeZ/view?usp=share_link into file artifacts/data_ingestion/data.csv]
[2025-02-23 01:22:10,746: INFO : 2399328493: Downloaded data from https://drive.google.com/file/d/1IcEWOO8q8VpidPF4p51wlHPXXUnNONeZ/view?usp=share_link into file artifacts/data_ingestion/data.csv]
[2025-02-23 01:26:08,365: INFO : common: yaml file: config/config.yaml loaded successfully]
[2025-02-23 01:26:08,367: INFO : common: yaml file: params.yaml loaded successfully]
[2025-02-23 01:26:08,368: INFO : common: created directory at artifacts]
[2025-02-23 01:26:08,368: INFO : common: created directory at artifacts/data_ingestion]
[2025-02-23 01:26:08,369: INFO : 835529877: Downloading data from https://drive.google.com/file/d/1IcEWOO8q8VpidPF4p51wlHPXXUnNONeZ/view?usp=share_link into file artifacts/data_ingestion/data.csv]
[2025-02-23 01:26:13,169: INFO : 835529877: Downloaded data from https://drive.google.com/file/d/1IcEWOO8q8VpidPF4p51wlHPXXUnNONeZ/view?usp=share_link into file artifacts/data_ingestion/data.csv]
[2025-02-23 01:44:38,993: INFO : main: >>>>>> stage Data Ingestion started <<<<<<<<]
[2025-02-23 01:44:38,994: INFO : common: yaml file: config/config.yaml loaded successfully]
[2025-02-23 01:44:38,995: INFO : common: yaml file: params.yaml loaded successfully]
[2025-02-23 01:44:38,995: INFO : common: created directory at artifacts]
[2025-02-23 01:44:38,995: INFO : common: created directory at artifacts/data_ingestion]
[2025-02-23 01:44:38,995: INFO : data_ingestion: Downloading data from https://drive.google.com/file/d/1IcEWOO8q8VpidPF4p51wlHPXXUnNONeZ/view?usp=share_link into file artifacts/data_ingestion/data.csv]
[2025-02-23 01:44:43,785: INFO : data_ingestion: Downloaded data from https://drive.google.com/file/d/1IcEWOO8q8VpidPF4p51wlHPXXUnNONeZ/view?usp=share_link into file artifacts/data_ingestion/data.csv]
[2025-02-23 01:44:43,786: INFO : main: >>>>>> stage Data Ingestion completed <<<<<<<<]
[2025-02-23 05:13:52,697: INFO : main: >>>>>> stage Data Ingestion started <<<<<<<<]
[2025-02-23 05:13:52,699: INFO : common: yaml file: config/config.yaml loaded successfully]
[2025-02-23 05:13:52,699: INFO : common: yaml file: params.yaml loaded successfully]
[2025-02-23 05:13:52,699: INFO : common: created directory at artifacts]
[2025-02-23 05:13:52,699: INFO : common: created directory at artifacts/data_ingestion]
[2025-02-23 05:13:52,699: INFO : data_ingestion: Downloading data from https://drive.google.com/file/d/1IcEWOO8q8VpidPF4p51wlHPXXUnNONeZ/view?usp=share_link into file artifacts/data_ingestion/data.csv]
[2025-02-23 05:13:57,683: INFO : data_ingestion: Downloaded data from https://drive.google.com/file/d/1IcEWOO8q8VpidPF4p51wlHPXXUnNONeZ/view?usp=share_link into file artifacts/data_ingestion/data.csv]
[2025-02-23 05:13:57,684: INFO : main: >>>>>> stage Data Ingestion completed <<<<<<<<]
[2025-02-23 07:30:51,189: INFO : common: yaml file: config/config.yaml loaded successfully]
[2025-02-23 07:30:51,200: INFO : common: yaml file: params.yaml loaded successfully]
[2025-02-23 07:30:51,201: INFO : common: created directory at artifacts]
[2025-02-23 07:30:51,203: INFO : common: created directory at artifacts/prepare_model]
[2025-02-23 07:31:33,967: INFO : common: yaml file: config/config.yaml loaded successfully]
[2025-02-23 07:31:33,973: INFO : common: yaml file: params.yaml loaded successfully]
[2025-02-23 07:31:33,978: INFO : common: created directory at artifacts]
[2025-02-23 07:31:40,250: INFO : common: yaml file: config/config.yaml loaded successfully]
[2025-02-23 07:31:40,252: INFO : common: yaml file: params.yaml loaded successfully]
[2025-02-23 07:31:40,253: INFO : common: created directory at artifacts]
[2025-02-23 07:31:40,253: INFO : common: created directory at artifacts/prepare_model]
[2025-02-23 07:32:51,702: INFO : common: yaml file: config/config.yaml loaded successfully]
[2025-02-23 07:32:51,704: INFO : common: yaml file: params.yaml loaded successfully]
[2025-02-23 07:32:51,705: INFO : common: created directory at artifacts]
[2025-02-23 07:32:51,707: INFO : common: created directory at artifacts/prepare_model]
[2025-02-23 07:33:16,559: INFO : common: yaml file: config/config.yaml loaded successfully]
[2025-02-23 07:33:16,562: INFO : common: yaml file: params.yaml loaded successfully]
[2025-02-23 07:33:16,564: INFO : common: created directory at artifacts]
[2025-02-23 07:33:16,566: INFO : common: created directory at artifacts/prepare_model]
[2025-02-23 07:34:22,498: INFO : common: yaml file: config/config.yaml loaded successfully]
[2025-02-23 07:34:22,502: INFO : common: yaml file: params.yaml loaded successfully]
[2025-02-23 07:34:22,504: INFO : common: created directory at artifacts]
[2025-02-23 07:34:22,505: INFO : common: created directory at artifacts/prepare_model]
[2025-02-23 07:35:25,476: INFO : common: yaml file: config/config.yaml loaded successfully]
[2025-02-23 07:35:25,477: INFO : common: yaml file: params.yaml loaded successfully]
[2025-02-23 07:35:25,478: INFO : common: created directory at artifacts]
[2025-02-23 07:35:25,479: INFO : common: created directory at artifacts/prepare_model]
[2025-02-23 07:35:50,463: INFO : common: yaml file: config/config.yaml loaded successfully]
[2025-02-23 07:35:50,471: INFO : common: yaml file: params.yaml loaded successfully]
[2025-02-23 07:35:50,472: INFO : common: created directory at artifacts]
[2025-02-23 07:35:50,475: INFO : common: created directory at artifacts/prepare_model]
[2025-02-23 07:36:26,754: INFO : common: yaml file: config/config.yaml loaded successfully]
[2025-02-23 07:36:26,760: INFO : common: yaml file: params.yaml loaded successfully]
[2025-02-23 07:36:26,761: INFO : common: created directory at artifacts]
[2025-02-23 07:36:26,762: INFO : common: created directory at artifacts/prepare_model]
[2025-02-23 07:37:10,772: INFO : common: yaml file: config/config.yaml loaded successfully]
[2025-02-23 07:37:10,776: INFO : common: yaml file: params.yaml loaded successfully]
[2025-02-23 07:37:10,779: INFO : common: created directory at artifacts]
[2025-02-23 07:37:10,780: INFO : common: created directory at artifacts/prepare_model]
[2025-02-23 07:38:31,743: INFO : common: yaml file: config/config.yaml loaded successfully]
[2025-02-23 07:38:31,745: INFO : common: yaml file: params.yaml loaded successfully]
[2025-02-23 07:38:31,746: INFO : common: created directory at artifacts]
[2025-02-23 07:38:31,747: INFO : common: created directory at artifacts/prepare_model]
[2025-02-23 07:41:06,835: INFO : common: yaml file: config/config.yaml loaded successfully]
[2025-02-23 07:41:06,858: INFO : common: yaml file: params.yaml loaded successfully]
[2025-02-23 07:41:06,869: INFO : common: created directory at artifacts]
[2025-02-23 07:41:06,876: INFO : common: created directory at artifacts/prepare_model]
[2025-02-23 07:43:47,565: INFO : common: yaml file: config/config.yaml loaded successfully]
[2025-02-23 07:43:47,567: INFO : common: yaml file: params.yaml loaded successfully]
[2025-02-23 07:43:47,568: INFO : common: created directory at artifacts]
[2025-02-23 07:43:47,569: INFO : common: created directory at artifacts/prepare_model]
[2025-02-23 07:45:05,226: INFO : common: yaml file: config/config.yaml loaded successfully]
[2025-02-23 07:45:05,229: INFO : common: yaml file: params.yaml loaded successfully]
[2025-02-23 07:45:05,231: INFO : common: created directory at artifacts]
[2025-02-23 07:45:05,236: INFO : common: created directory at artifacts/prepare_model]
[2025-02-23 07:45:05,251: INFO : common: yaml file: config/config.yaml loaded successfully]
[2025-02-23 07:45:05,254: INFO : common: yaml file: params.yaml loaded successfully]
[2025-02-23 07:45:05,255: INFO : common: created directory at artifacts]
[2025-02-23 07:45:05,256: INFO : common: created directory at artifacts/prepare_model]
[2025-02-23 07:45:41,319: INFO : common: yaml file: config/config.yaml loaded successfully]
[2025-02-23 07:45:41,323: INFO : common: yaml file: params.yaml loaded successfully]
[2025-02-23 07:45:41,328: INFO : common: created directory at artifacts]
[2025-02-23 07:45:41,329: INFO : common: created directory at artifacts/prepare_model]
[2025-02-23 07:45:41,347: INFO : common: yaml file: config/config.yaml loaded successfully]
[2025-02-23 07:45:41,350: INFO : common: yaml file: params.yaml loaded successfully]
[2025-02-23 07:45:41,352: INFO : common: created directory at artifacts]
[2025-02-23 07:45:41,353: INFO : common: created directory at artifacts/prepare_model]
[2025-02-23 07:46:42,074: INFO : common: yaml file: config/config.yaml loaded successfully]
[2025-02-23 07:46:42,075: INFO : common: yaml file: params.yaml loaded successfully]
[2025-02-23 07:46:42,076: INFO : common: created directory at artifacts]
[2025-02-23 07:46:42,077: INFO : common: created directory at artifacts/prepare_model]
[2025-02-23 07:46:42,083: INFO : common: yaml file: config/config.yaml loaded successfully]
[2025-02-23 07:46:42,084: INFO : common: yaml file: params.yaml loaded successfully]
[2025-02-23 07:46:42,085: INFO : common: created directory at artifacts]
[2025-02-23 07:46:42,086: INFO : common: created directory at artifacts/prepare_model]
[2025-02-23 07:47:52,314: INFO : common: yaml file: config/config.yaml loaded successfully]
[2025-02-23 07:47:52,321: INFO : common: yaml file: params.yaml loaded successfully]
[2025-02-23 07:47:52,322: INFO : common: created directory at artifacts]
[2025-02-23 07:47:52,323: INFO : common: created directory at artifacts/prepare_model]
[2025-02-23 07:49:36,176: INFO : common: yaml file: config/config.yaml loaded successfully]
[2025-02-23 07:49:36,183: INFO : common: yaml file: params.yaml loaded successfully]
[2025-02-23 07:49:36,190: INFO : common: created directory at artifacts]
[2025-02-23 07:49:36,204: INFO : common: created directory at artifacts/prepare_model]
[2025-02-23 08:25:51,095: ERROR : main: name 'STAGE_NAME' is not defined]
Traceback (most recent call last):
  File "main.py", line 8, in <module>
    logger.info(f'Stage {STAGE_NAME} started')
NameError: name 'STAGE_NAME' is not defined
[2025-02-23 08:26:09,539: INFO : main: Stage data-ingestion started]
[2025-02-23 08:26:09,540: INFO : common: yaml file: config/config.yaml loaded successfully]
[2025-02-23 08:26:09,542: INFO : common: yaml file: params.yaml loaded successfully]
[2025-02-23 08:26:09,542: INFO : common: created directory at artifacts]
[2025-02-23 08:26:09,542: INFO : common: created directory at artifacts/data_ingestion]
[2025-02-23 08:26:09,542: INFO : data_ingestion: Downloading data from https://drive.google.com/file/d/1IcEWOO8q8VpidPF4p51wlHPXXUnNONeZ/view?usp=share_link into file artifacts/data_ingestion/data.csv]
[2025-02-23 08:26:15,069: INFO : data_ingestion: Downloaded data from https://drive.google.com/file/d/1IcEWOO8q8VpidPF4p51wlHPXXUnNONeZ/view?usp=share_link into file artifacts/data_ingestion/data.csv]
[2025-02-23 08:26:15,069: INFO : main: data-ingestion completed successfully...]
[2025-02-23 08:26:15,069: INFO : main: Stage data-ingestion started]
[2025-02-23 08:26:15,069: INFO : common: created directory at artifacts/setup_model]
[2025-02-23 08:26:16,886: INFO : main: setup-model completed successfully...]
[2025-02-23 11:04:09,782: INFO : common: yaml file: config/config.yaml loaded successfully]
[2025-02-23 11:04:09,787: INFO : common: yaml file: params.yaml loaded successfully]
[2025-02-23 11:04:09,788: INFO : common: created directory at artifacts]
[2025-02-23 11:04:09,788: INFO : common: created directory at artifacts/training]
[2025-02-23 11:04:43,606: INFO : common: yaml file: config/config.yaml loaded successfully]
[2025-02-23 11:04:43,611: INFO : common: yaml file: params.yaml loaded successfully]
[2025-02-23 11:04:43,612: INFO : common: created directory at artifacts]
[2025-02-23 11:04:43,612: INFO : common: created directory at artifacts/training]
[2025-02-23 11:04:53,228: INFO : common: yaml file: config/config.yaml loaded successfully]
[2025-02-23 11:04:53,230: INFO : common: yaml file: params.yaml loaded successfully]
[2025-02-23 11:04:53,230: INFO : common: created directory at artifacts]
[2025-02-23 11:04:53,231: INFO : common: created directory at artifacts/training]
[2025-02-23 11:05:02,653: INFO : common: yaml file: config/config.yaml loaded successfully]
[2025-02-23 11:05:02,658: INFO : common: yaml file: params.yaml loaded successfully]
[2025-02-23 11:05:02,661: INFO : common: created directory at artifacts]
[2025-02-23 11:05:02,662: INFO : common: created directory at artifacts/training]
[2025-02-23 11:05:12,629: INFO : common: yaml file: config/config.yaml loaded successfully]
[2025-02-23 11:05:12,634: INFO : common: yaml file: params.yaml loaded successfully]
[2025-02-23 11:05:12,636: INFO : common: created directory at artifacts]
[2025-02-23 11:05:12,638: INFO : common: created directory at artifacts/training]
[2025-02-23 11:06:23,042: INFO : common: yaml file: config/config.yaml loaded successfully]
[2025-02-23 11:06:23,045: INFO : common: yaml file: params.yaml loaded successfully]
[2025-02-23 11:06:23,046: INFO : common: created directory at artifacts]
[2025-02-23 11:06:23,046: INFO : common: created directory at artifacts/training]
[2025-02-23 11:06:43,159: INFO : common: yaml file: config/config.yaml loaded successfully]
[2025-02-23 11:06:43,160: INFO : common: yaml file: params.yaml loaded successfully]
[2025-02-23 11:06:43,161: INFO : common: created directory at artifacts]
[2025-02-23 11:06:43,162: INFO : common: created directory at artifacts/training]
[2025-02-23 11:13:41,696: INFO : common: yaml file: config/config.yaml loaded successfully]
[2025-02-23 11:13:41,699: INFO : common: yaml file: params.yaml loaded successfully]
[2025-02-23 11:13:41,699: INFO : common: created directory at artifacts]
[2025-02-23 11:13:41,700: INFO : common: created directory at artifacts/training]
[2025-02-23 11:13:57,344: INFO : common: yaml file: config/config.yaml loaded successfully]
[2025-02-23 11:13:57,346: INFO : common: yaml file: params.yaml loaded successfully]
[2025-02-23 11:13:57,347: INFO : common: created directory at artifacts]
[2025-02-23 11:13:57,348: INFO : common: created directory at artifacts/training]
[2025-02-23 11:14:18,923: INFO : common: yaml file: config/config.yaml loaded successfully]
[2025-02-23 11:14:18,925: INFO : common: yaml file: params.yaml loaded successfully]
[2025-02-23 11:14:18,925: INFO : common: created directory at artifacts]
[2025-02-23 11:14:18,926: INFO : common: created directory at artifacts/training]
[2025-02-23 11:14:55,718: INFO : common: yaml file: config/config.yaml loaded successfully]
[2025-02-23 11:14:55,721: INFO : common: yaml file: params.yaml loaded successfully]
[2025-02-23 11:14:55,722: INFO : common: created directory at artifacts]
[2025-02-23 11:14:55,722: INFO : common: created directory at artifacts/training]
[2025-02-23 11:15:26,601: INFO : common: yaml file: config/config.yaml loaded successfully]
[2025-02-23 11:15:26,603: INFO : common: yaml file: params.yaml loaded successfully]
[2025-02-23 11:15:26,604: INFO : common: created directory at artifacts]
[2025-02-23 11:15:26,605: INFO : common: created directory at artifacts/training]
[2025-02-23 11:21:34,361: INFO : common: yaml file: config/config.yaml loaded successfully]
[2025-02-23 11:21:34,367: INFO : common: yaml file: params.yaml loaded successfully]
[2025-02-23 11:21:34,368: INFO : common: created directory at artifacts]
[2025-02-23 11:21:34,369: INFO : common: created directory at artifacts/training]
[2025-02-23 11:26:23,572: INFO : common: yaml file: config/config.yaml loaded successfully]
[2025-02-23 11:26:23,577: INFO : common: yaml file: params.yaml loaded successfully]
[2025-02-23 11:26:23,580: INFO : common: created directory at artifacts]
[2025-02-23 11:26:23,584: INFO : common: created directory at artifacts/training]
[2025-02-23 11:28:53,661: INFO : common: yaml file: config/config.yaml loaded successfully]
[2025-02-23 11:28:53,666: INFO : common: yaml file: params.yaml loaded successfully]
[2025-02-23 11:28:53,670: INFO : common: created directory at artifacts]
[2025-02-23 11:28:53,674: INFO : common: created directory at artifacts/training]
[2025-02-23 11:29:58,367: INFO : main: Stage data-ingestion started]
[2025-02-23 11:29:58,369: INFO : common: yaml file: config/config.yaml loaded successfully]
[2025-02-23 11:29:58,371: INFO : common: yaml file: params.yaml loaded successfully]
[2025-02-23 11:29:58,372: INFO : common: created directory at artifacts]
[2025-02-23 11:29:58,372: INFO : common: created directory at artifacts/data_ingestion]
[2025-02-23 11:29:58,372: INFO : data_ingestion: Downloading data from https://drive.google.com/file/d/1IcEWOO8q8VpidPF4p51wlHPXXUnNONeZ/view?usp=share_link into file artifacts/data_ingestion/data.csv]
[2025-02-23 11:30:05,338: INFO : data_ingestion: Downloaded data from https://drive.google.com/file/d/1IcEWOO8q8VpidPF4p51wlHPXXUnNONeZ/view?usp=share_link into file artifacts/data_ingestion/data.csv]
[2025-02-23 11:30:05,339: INFO : main: data-ingestion completed successfully...]
[2025-02-23 11:30:05,339: INFO : main: Stage data-ingestion started]
[2025-02-23 11:30:05,340: INFO : common: created directory at artifacts/setup_model]
[2025-02-23 11:30:08,116: INFO : main: setup-model completed successfully...]
[2025-02-23 11:30:26,525: INFO : common: yaml file: config/config.yaml loaded successfully]
[2025-02-23 11:30:26,527: INFO : common: yaml file: params.yaml loaded successfully]
[2025-02-23 11:30:26,532: INFO : common: created directory at artifacts]
[2025-02-23 11:30:26,534: INFO : common: created directory at artifacts/training]
[2025-02-23 11:31:23,086: INFO : common: yaml file: config/config.yaml loaded successfully]
[2025-02-23 11:31:23,091: INFO : common: yaml file: params.yaml loaded successfully]
[2025-02-23 11:31:23,092: INFO : common: created directory at artifacts]
[2025-02-23 11:31:23,093: INFO : common: created directory at artifacts/training]
[2025-02-23 11:32:22,856: INFO : common: yaml file: config/config.yaml loaded successfully]
[2025-02-23 11:32:22,859: INFO : common: yaml file: params.yaml loaded successfully]
[2025-02-23 11:32:22,860: INFO : common: created directory at artifacts]
[2025-02-23 11:32:22,861: INFO : common: created directory at artifacts/training]
[2025-02-23 11:34:48,486: INFO : common: yaml file: config/config.yaml loaded successfully]
[2025-02-23 11:34:48,489: INFO : common: yaml file: params.yaml loaded successfully]
[2025-02-23 11:34:48,490: INFO : common: created directory at artifacts]
[2025-02-23 11:34:48,491: INFO : common: created directory at artifacts/training]
[2025-02-23 11:42:40,375: INFO : common: yaml file: config/config.yaml loaded successfully]
[2025-02-23 11:42:40,378: INFO : common: yaml file: params.yaml loaded successfully]
[2025-02-23 11:42:40,379: INFO : common: created directory at artifacts]
[2025-02-23 11:42:40,380: INFO : common: created directory at artifacts/training]
[2025-02-23 11:49:29,869: INFO : common: yaml file: config/config.yaml loaded successfully]
[2025-02-23 11:49:29,882: INFO : common: yaml file: params.yaml loaded successfully]
[2025-02-23 11:49:29,901: INFO : common: created directory at artifacts]
[2025-02-23 11:49:29,911: INFO : common: created directory at artifacts/training]
[2025-02-23 11:57:42,320: INFO : common: yaml file: config/config.yaml loaded successfully]
[2025-02-23 11:57:42,322: INFO : common: yaml file: params.yaml loaded successfully]
[2025-02-23 11:57:42,322: INFO : common: created directory at artifacts]
[2025-02-23 11:57:42,323: INFO : common: created directory at artifacts/training]
[2025-02-23 12:23:04,198: INFO : main: Stage data-ingestion started]
[2025-02-23 12:23:04,200: INFO : common: yaml file: config/config.yaml loaded successfully]
[2025-02-23 12:23:04,200: INFO : common: yaml file: params.yaml loaded successfully]
[2025-02-23 12:23:04,200: INFO : common: created directory at artifacts]
[2025-02-23 12:23:04,200: INFO : common: created directory at artifacts/data_ingestion]
[2025-02-23 12:23:04,200: INFO : data_ingestion: Downloading data from https://drive.google.com/file/d/1IcEWOO8q8VpidPF4p51wlHPXXUnNONeZ/view?usp=share_link into file artifacts/data_ingestion/data.csv]
[2025-02-23 12:23:09,578: INFO : data_ingestion: Downloaded data from https://drive.google.com/file/d/1IcEWOO8q8VpidPF4p51wlHPXXUnNONeZ/view?usp=share_link into file artifacts/data_ingestion/data.csv]
[2025-02-23 12:23:09,579: INFO : main: data-ingestion completed successfully...]
[2025-02-23 12:23:09,579: INFO : main: Stage setup-model started]
[2025-02-23 12:23:09,579: INFO : common: created directory at artifacts/setup_model]
[2025-02-23 12:23:11,028: INFO : main: setup-model completed successfully...]
[2025-02-23 12:23:11,032: INFO : main: Stage training started]
[2025-02-23 12:23:11,032: INFO : common: created directory at artifacts/training]
[2025-02-23 12:23:11,824: ERROR : main: name 'CustomDataset' is not defined]
Traceback (most recent call last):
  File "main.py", line 30, in <module>
    trainer.split_data()
  File "/Users/ernestodavidserizeportela/WorkSpace/toxic-chat-clf/src/bert_toxic_chat_clf/components/trainer.py", line 41, in split_data
    training_set = CustomDataset(train_dataset, self.config.params_max_len)
NameError: name 'CustomDataset' is not defined
[2025-02-23 12:23:35,607: INFO : main: Stage data-ingestion started]
[2025-02-23 12:23:35,607: INFO : common: yaml file: config/config.yaml loaded successfully]
[2025-02-23 12:23:35,608: INFO : common: yaml file: params.yaml loaded successfully]
[2025-02-23 12:23:35,608: INFO : common: created directory at artifacts]
[2025-02-23 12:23:35,608: INFO : common: created directory at artifacts/data_ingestion]
[2025-02-23 12:23:35,608: INFO : data_ingestion: Downloading data from https://drive.google.com/file/d/1IcEWOO8q8VpidPF4p51wlHPXXUnNONeZ/view?usp=share_link into file artifacts/data_ingestion/data.csv]
[2025-02-23 12:23:47,298: INFO : data_ingestion: Downloaded data from https://drive.google.com/file/d/1IcEWOO8q8VpidPF4p51wlHPXXUnNONeZ/view?usp=share_link into file artifacts/data_ingestion/data.csv]
[2025-02-23 12:23:47,299: INFO : main: data-ingestion completed successfully...]
[2025-02-23 12:23:47,299: INFO : main: Stage setup-model started]
[2025-02-23 12:23:47,299: INFO : common: created directory at artifacts/setup_model]
[2025-02-23 12:23:52,409: INFO : main: setup-model completed successfully...]
[2025-02-23 12:23:52,409: INFO : main: Stage training started]
[2025-02-23 12:23:52,409: INFO : common: created directory at artifacts/training]
[2025-02-23 12:38:32,044: INFO : main: training completed successfully...]
[2025-02-23 18:29:19,227: INFO : main: Stage data-ingestion started]
[2025-02-23 18:29:19,228: INFO : common: yaml file: config/config.yaml loaded successfully]
[2025-02-23 18:29:19,229: INFO : common: yaml file: params.yaml loaded successfully]
[2025-02-23 18:29:19,229: INFO : common: created directory at artifacts]
[2025-02-23 18:29:19,229: INFO : common: created directory at artifacts/data_ingestion]
[2025-02-23 18:29:19,229: INFO : data_ingestion: Downloading data from https://drive.google.com/file/d/1IcEWOO8q8VpidPF4p51wlHPXXUnNONeZ/view?usp=share_link into file artifacts/data_ingestion/data.csv]
[2025-02-23 18:29:19,236: ERROR : main: HTTPSConnectionPool(host='drive.google.com', port=443): Max retries exceeded with url: /uc?/export=download&id=1IcEWOO8q8VpidPF4p51wlHPXXUnNONeZ (Caused by NameResolutionError("<urllib3.connection.HTTPSConnection object at 0x31b0fa5b0>: Failed to resolve 'drive.google.com' ([Errno 8] nodename nor servname provided, or not known)"))]
Traceback (most recent call last):
  File "/opt/homebrew/anaconda3/envs/bert/lib/python3.8/site-packages/urllib3/connection.py", line 199, in _new_conn
    sock = connection.create_connection(
  File "/opt/homebrew/anaconda3/envs/bert/lib/python3.8/site-packages/urllib3/util/connection.py", line 60, in create_connection
    for res in socket.getaddrinfo(host, port, family, socket.SOCK_STREAM):
  File "/opt/homebrew/anaconda3/envs/bert/lib/python3.8/socket.py", line 930, in getaddrinfo
    for res in _socket.getaddrinfo(host, port, family, type, proto, flags):
socket.gaierror: [Errno 8] nodename nor servname provided, or not known

The above exception was the direct cause of the following exception:

Traceback (most recent call last):
  File "/opt/homebrew/anaconda3/envs/bert/lib/python3.8/site-packages/urllib3/connectionpool.py", line 789, in urlopen
    response = self._make_request(
  File "/opt/homebrew/anaconda3/envs/bert/lib/python3.8/site-packages/urllib3/connectionpool.py", line 490, in _make_request
    raise new_e
  File "/opt/homebrew/anaconda3/envs/bert/lib/python3.8/site-packages/urllib3/connectionpool.py", line 466, in _make_request
    self._validate_conn(conn)
  File "/opt/homebrew/anaconda3/envs/bert/lib/python3.8/site-packages/urllib3/connectionpool.py", line 1095, in _validate_conn
    conn.connect()
  File "/opt/homebrew/anaconda3/envs/bert/lib/python3.8/site-packages/urllib3/connection.py", line 693, in connect
    self.sock = sock = self._new_conn()
  File "/opt/homebrew/anaconda3/envs/bert/lib/python3.8/site-packages/urllib3/connection.py", line 206, in _new_conn
    raise NameResolutionError(self.host, self, e) from e
urllib3.exceptions.NameResolutionError: <urllib3.connection.HTTPSConnection object at 0x31b0fa5b0>: Failed to resolve 'drive.google.com' ([Errno 8] nodename nor servname provided, or not known)

The above exception was the direct cause of the following exception:

Traceback (most recent call last):
  File "/opt/homebrew/anaconda3/envs/bert/lib/python3.8/site-packages/requests/adapters.py", line 667, in send
    resp = conn.urlopen(
  File "/opt/homebrew/anaconda3/envs/bert/lib/python3.8/site-packages/urllib3/connectionpool.py", line 843, in urlopen
    retries = retries.increment(
  File "/opt/homebrew/anaconda3/envs/bert/lib/python3.8/site-packages/urllib3/util/retry.py", line 519, in increment
    raise MaxRetryError(_pool, url, reason) from reason  # type: ignore[arg-type]
urllib3.exceptions.MaxRetryError: HTTPSConnectionPool(host='drive.google.com', port=443): Max retries exceeded with url: /uc?/export=download&id=1IcEWOO8q8VpidPF4p51wlHPXXUnNONeZ (Caused by NameResolutionError("<urllib3.connection.HTTPSConnection object at 0x31b0fa5b0>: Failed to resolve 'drive.google.com' ([Errno 8] nodename nor servname provided, or not known)"))

During handling of the above exception, another exception occurred:

Traceback (most recent call last):
  File "main.py", line 13, in <module>
    data_ingestion.download_file()
  File "/Users/ernestodavidserizeportela/WorkSpace/toxic-chat-clf/src/bert_toxic_chat_clf/components/data_ingestion.py", line 30, in download_file
    raise e
  File "/Users/ernestodavidserizeportela/WorkSpace/toxic-chat-clf/src/bert_toxic_chat_clf/components/data_ingestion.py", line 25, in download_file
    gdown.download(url, local_file)
  File "/opt/homebrew/anaconda3/envs/bert/lib/python3.8/site-packages/gdown/download.py", line 202, in download
    res = sess.get(url, stream=True, verify=verify)
  File "/opt/homebrew/anaconda3/envs/bert/lib/python3.8/site-packages/requests/sessions.py", line 602, in get
    return self.request("GET", url, **kwargs)
  File "/opt/homebrew/anaconda3/envs/bert/lib/python3.8/site-packages/requests/sessions.py", line 589, in request
    resp = self.send(prep, **send_kwargs)
  File "/opt/homebrew/anaconda3/envs/bert/lib/python3.8/site-packages/requests/sessions.py", line 703, in send
    r = adapter.send(request, **kwargs)
  File "/opt/homebrew/anaconda3/envs/bert/lib/python3.8/site-packages/requests/adapters.py", line 700, in send
    raise ConnectionError(e, request=request)
requests.exceptions.ConnectionError: HTTPSConnectionPool(host='drive.google.com', port=443): Max retries exceeded with url: /uc?/export=download&id=1IcEWOO8q8VpidPF4p51wlHPXXUnNONeZ (Caused by NameResolutionError("<urllib3.connection.HTTPSConnection object at 0x31b0fa5b0>: Failed to resolve 'drive.google.com' ([Errno 8] nodename nor servname provided, or not known)"))
[2025-02-23 18:29:47,448: INFO : main: Stage data-ingestion started]
[2025-02-23 18:29:47,449: INFO : common: yaml file: config/config.yaml loaded successfully]
[2025-02-23 18:29:47,449: INFO : common: yaml file: params.yaml loaded successfully]
[2025-02-23 18:29:47,449: INFO : common: created directory at artifacts]
[2025-02-23 18:29:47,449: INFO : common: created directory at artifacts/data_ingestion]
[2025-02-23 18:29:47,449: INFO : data_ingestion: Downloading data from https://drive.google.com/file/d/1IcEWOO8q8VpidPF4p51wlHPXXUnNONeZ/view?usp=share_link into file artifacts/data_ingestion/data.csv]
[2025-02-23 18:29:55,470: INFO : data_ingestion: Downloaded data from https://drive.google.com/file/d/1IcEWOO8q8VpidPF4p51wlHPXXUnNONeZ/view?usp=share_link into file artifacts/data_ingestion/data.csv]
[2025-02-23 18:29:55,470: INFO : main: data-ingestion completed successfully...]
[2025-02-23 18:29:55,470: INFO : main: Stage setup-model started]
[2025-02-23 18:29:55,471: INFO : common: created directory at artifacts/setup_model]
[2025-02-23 18:29:57,369: INFO : main: setup-model completed successfully...]
[2025-02-23 18:29:57,370: INFO : main: Stage training started]
[2025-02-23 18:29:57,370: INFO : common: created directory at artifacts/training]
[2025-02-23 20:05:33,340: INFO : main: Stage data-ingestion started]
[2025-02-23 20:05:33,341: INFO : common: yaml file: config/config.yaml loaded successfully]
[2025-02-23 20:05:33,341: INFO : common: yaml file: params.yaml loaded successfully]
[2025-02-23 20:05:33,341: INFO : common: created directory at artifacts]
[2025-02-23 20:05:33,341: INFO : common: created directory at artifacts/data_ingestion]
[2025-02-23 20:05:33,341: INFO : data_ingestion: Downloading data from https://drive.google.com/file/d/1IcEWOO8q8VpidPF4p51wlHPXXUnNONeZ/view?usp=share_link into file artifacts/data_ingestion/data.csv]
[2025-02-23 20:05:42,306: INFO : data_ingestion: Downloaded data from https://drive.google.com/file/d/1IcEWOO8q8VpidPF4p51wlHPXXUnNONeZ/view?usp=share_link into file artifacts/data_ingestion/data.csv]
[2025-02-23 20:05:42,306: INFO : main: data-ingestion completed successfully...]
[2025-02-23 20:05:42,306: INFO : main: Stage split-data started]
[2025-02-23 20:05:42,307: INFO : common: created directory at artifacts/data_split]
[2025-02-23 20:05:42,307: INFO : common: created directory at artifacts/data_split/train]
[2025-02-23 20:05:42,308: INFO : common: created directory at artifacts/data_split/test]
[2025-02-23 20:05:42,308: ERROR : main: __init__() missing 1 required positional argument: 'params_train_size']
Traceback (most recent call last):
  File "main.py", line 18, in <module>
    data_split_config = config.get_data_split_config()
  File "/Users/ernestodavidserizeportela/WorkSpace/toxic-chat-clf/src/bert_toxic_chat_clf/config/configuration.py", line 42, in get_data_split_config
    data_split_config = DataSplitConfig(
TypeError: __init__() missing 1 required positional argument: 'params_train_size'
[2025-02-23 20:09:24,438: INFO : main: Stage data-ingestion started]
[2025-02-23 20:09:24,439: INFO : common: yaml file: config/config.yaml loaded successfully]
[2025-02-23 20:09:24,439: INFO : common: yaml file: params.yaml loaded successfully]
[2025-02-23 20:09:24,440: INFO : common: created directory at artifacts]
[2025-02-23 20:09:24,440: INFO : common: created directory at artifacts/data_ingestion]
[2025-02-23 20:09:24,440: INFO : data_ingestion: Downloading data from https://drive.google.com/file/d/1IcEWOO8q8VpidPF4p51wlHPXXUnNONeZ/view?usp=share_link into file artifacts/data_ingestion/data.csv]
[2025-02-23 20:09:29,840: INFO : data_ingestion: Downloaded data from https://drive.google.com/file/d/1IcEWOO8q8VpidPF4p51wlHPXXUnNONeZ/view?usp=share_link into file artifacts/data_ingestion/data.csv]
[2025-02-23 20:09:29,840: INFO : main: data-ingestion completed successfully...]
[2025-02-23 20:09:29,840: INFO : main: Stage split-data started]
[2025-02-23 20:09:29,841: INFO : common: created directory at artifacts/data_split]
[2025-02-23 20:09:29,841: INFO : common: created directory at artifacts/data_split/train]
[2025-02-23 20:09:29,841: INFO : common: created directory at artifacts/data_split/test]
[2025-02-23 20:09:29,841: ERROR : main: name 'DataSplit' is not defined]
Traceback (most recent call last):
  File "main.py", line 19, in <module>
    data_split = DataSplit(config=data_ingestion_config)
NameError: name 'DataSplit' is not defined
[2025-02-23 20:10:08,825: INFO : main: Stage data-ingestion started]
[2025-02-23 20:10:08,826: INFO : common: yaml file: config/config.yaml loaded successfully]
[2025-02-23 20:10:08,827: INFO : common: yaml file: params.yaml loaded successfully]
[2025-02-23 20:10:08,827: INFO : common: created directory at artifacts]
[2025-02-23 20:10:08,827: INFO : common: created directory at artifacts/data_ingestion]
[2025-02-23 20:10:08,827: INFO : data_ingestion: Downloading data from https://drive.google.com/file/d/1IcEWOO8q8VpidPF4p51wlHPXXUnNONeZ/view?usp=share_link into file artifacts/data_ingestion/data.csv]
[2025-02-23 20:10:19,506: INFO : data_ingestion: Downloaded data from https://drive.google.com/file/d/1IcEWOO8q8VpidPF4p51wlHPXXUnNONeZ/view?usp=share_link into file artifacts/data_ingestion/data.csv]
[2025-02-23 20:10:19,507: INFO : main: data-ingestion completed successfully...]
[2025-02-23 20:10:19,507: INFO : main: Stage split-data started]
[2025-02-23 20:10:19,507: INFO : common: created directory at artifacts/data_split]
[2025-02-23 20:10:19,507: INFO : common: created directory at artifacts/data_split/train]
[2025-02-23 20:10:19,507: INFO : common: created directory at artifacts/data_split/test]
[2025-02-23 20:10:19,508: ERROR : main: 'DataIngestionConfig' object has no attribute 'data_path']
Traceback (most recent call last):
  File "main.py", line 21, in <module>
    data_split.load_data()
  File "/Users/ernestodavidserizeportela/WorkSpace/toxic-chat-clf/src/bert_toxic_chat_clf/components/data_split.py", line 15, in load_data
    self.df = pd.read_csv(self.config.data_path)
AttributeError: 'DataIngestionConfig' object has no attribute 'data_path'
[2025-02-23 20:10:59,488: INFO : main: Stage data-ingestion started]
[2025-02-23 20:10:59,489: INFO : common: yaml file: config/config.yaml loaded successfully]
[2025-02-23 20:10:59,490: INFO : common: yaml file: params.yaml loaded successfully]
[2025-02-23 20:10:59,490: INFO : common: created directory at artifacts]
[2025-02-23 20:10:59,490: INFO : common: created directory at artifacts/data_ingestion]
[2025-02-23 20:10:59,490: INFO : data_ingestion: Downloading data from https://drive.google.com/file/d/1IcEWOO8q8VpidPF4p51wlHPXXUnNONeZ/view?usp=share_link into file artifacts/data_ingestion/data.csv]
[2025-02-23 20:11:05,052: INFO : data_ingestion: Downloaded data from https://drive.google.com/file/d/1IcEWOO8q8VpidPF4p51wlHPXXUnNONeZ/view?usp=share_link into file artifacts/data_ingestion/data.csv]
[2025-02-23 20:11:05,052: INFO : main: data-ingestion completed successfully...]
[2025-02-23 20:11:05,052: INFO : main: Stage split-data started]
[2025-02-23 20:11:05,052: INFO : common: created directory at artifacts/data_split]
[2025-02-23 20:11:05,052: INFO : common: created directory at artifacts/data_split/train]
[2025-02-23 20:11:05,052: INFO : common: created directory at artifacts/data_split/test]
[2025-02-23 20:11:05,061: ERROR : main: name 'train_size' is not defined]
Traceback (most recent call last):
  File "main.py", line 22, in <module>
    data_split.split()
  File "/Users/ernestodavidserizeportela/WorkSpace/toxic-chat-clf/src/bert_toxic_chat_clf/components/data_split.py", line 23, in split
    train_dataset=df.sample(frac=train_size,random_state=42)
NameError: name 'train_size' is not defined
[2025-02-23 20:12:01,243: INFO : main: Stage data-ingestion started]
[2025-02-23 20:12:01,244: INFO : common: yaml file: config/config.yaml loaded successfully]
[2025-02-23 20:12:01,245: INFO : common: yaml file: params.yaml loaded successfully]
[2025-02-23 20:12:01,245: INFO : common: created directory at artifacts]
[2025-02-23 20:12:01,245: INFO : common: created directory at artifacts/data_ingestion]
[2025-02-23 20:12:01,245: INFO : data_ingestion: Downloading data from https://drive.google.com/file/d/1IcEWOO8q8VpidPF4p51wlHPXXUnNONeZ/view?usp=share_link into file artifacts/data_ingestion/data.csv]
[2025-02-23 20:13:18,626: ERROR : main: HTTPSConnectionPool(host='doc-0o-1o-docs.googleusercontent.com', port=443): Max retries exceeded with url: /docs/securesc/ha0ro937gcuc7l7deffksulhg5h7mbp1/kul3p0d38qp99q7jpc8f7bmv0jhcrg4e/1740359475000/06901382624441071134/*/1IcEWOO8q8VpidPF4p51wlHPXXUnNONeZ?uuid=5a6dc7fc-074c-4f12-bc8c-729e90842e83 (Caused by NewConnectionError('<urllib3.connection.HTTPSConnection object at 0x3163d5310>: Failed to establish a new connection: [Errno 60] Operation timed out'))]
Traceback (most recent call last):
  File "/opt/homebrew/anaconda3/envs/bert/lib/python3.8/site-packages/urllib3/connection.py", line 199, in _new_conn
    sock = connection.create_connection(
  File "/opt/homebrew/anaconda3/envs/bert/lib/python3.8/site-packages/urllib3/util/connection.py", line 85, in create_connection
    raise err
  File "/opt/homebrew/anaconda3/envs/bert/lib/python3.8/site-packages/urllib3/util/connection.py", line 73, in create_connection
    sock.connect(sa)
TimeoutError: [Errno 60] Operation timed out

The above exception was the direct cause of the following exception:

Traceback (most recent call last):
  File "/opt/homebrew/anaconda3/envs/bert/lib/python3.8/site-packages/urllib3/connectionpool.py", line 789, in urlopen
    response = self._make_request(
  File "/opt/homebrew/anaconda3/envs/bert/lib/python3.8/site-packages/urllib3/connectionpool.py", line 490, in _make_request
    raise new_e
  File "/opt/homebrew/anaconda3/envs/bert/lib/python3.8/site-packages/urllib3/connectionpool.py", line 466, in _make_request
    self._validate_conn(conn)
  File "/opt/homebrew/anaconda3/envs/bert/lib/python3.8/site-packages/urllib3/connectionpool.py", line 1095, in _validate_conn
    conn.connect()
  File "/opt/homebrew/anaconda3/envs/bert/lib/python3.8/site-packages/urllib3/connection.py", line 693, in connect
    self.sock = sock = self._new_conn()
  File "/opt/homebrew/anaconda3/envs/bert/lib/python3.8/site-packages/urllib3/connection.py", line 214, in _new_conn
    raise NewConnectionError(
urllib3.exceptions.NewConnectionError: <urllib3.connection.HTTPSConnection object at 0x3163d5310>: Failed to establish a new connection: [Errno 60] Operation timed out

The above exception was the direct cause of the following exception:

Traceback (most recent call last):
  File "/opt/homebrew/anaconda3/envs/bert/lib/python3.8/site-packages/requests/adapters.py", line 667, in send
    resp = conn.urlopen(
  File "/opt/homebrew/anaconda3/envs/bert/lib/python3.8/site-packages/urllib3/connectionpool.py", line 843, in urlopen
    retries = retries.increment(
  File "/opt/homebrew/anaconda3/envs/bert/lib/python3.8/site-packages/urllib3/util/retry.py", line 519, in increment
    raise MaxRetryError(_pool, url, reason) from reason  # type: ignore[arg-type]
urllib3.exceptions.MaxRetryError: HTTPSConnectionPool(host='doc-0o-1o-docs.googleusercontent.com', port=443): Max retries exceeded with url: /docs/securesc/ha0ro937gcuc7l7deffksulhg5h7mbp1/kul3p0d38qp99q7jpc8f7bmv0jhcrg4e/1740359475000/06901382624441071134/*/1IcEWOO8q8VpidPF4p51wlHPXXUnNONeZ?uuid=5a6dc7fc-074c-4f12-bc8c-729e90842e83 (Caused by NewConnectionError('<urllib3.connection.HTTPSConnection object at 0x3163d5310>: Failed to establish a new connection: [Errno 60] Operation timed out'))

During handling of the above exception, another exception occurred:

Traceback (most recent call last):
  File "main.py", line 14, in <module>
    data_ingestion.download_file()
  File "/Users/ernestodavidserizeportela/WorkSpace/toxic-chat-clf/src/bert_toxic_chat_clf/components/data_ingestion.py", line 30, in download_file
    raise e
  File "/Users/ernestodavidserizeportela/WorkSpace/toxic-chat-clf/src/bert_toxic_chat_clf/components/data_ingestion.py", line 25, in download_file
    gdown.download(url, local_file)
  File "/opt/homebrew/anaconda3/envs/bert/lib/python3.8/site-packages/gdown/download.py", line 202, in download
    res = sess.get(url, stream=True, verify=verify)
  File "/opt/homebrew/anaconda3/envs/bert/lib/python3.8/site-packages/requests/sessions.py", line 602, in get
    return self.request("GET", url, **kwargs)
  File "/opt/homebrew/anaconda3/envs/bert/lib/python3.8/site-packages/requests/sessions.py", line 589, in request
    resp = self.send(prep, **send_kwargs)
  File "/opt/homebrew/anaconda3/envs/bert/lib/python3.8/site-packages/requests/sessions.py", line 724, in send
    history = [resp for resp in gen]
  File "/opt/homebrew/anaconda3/envs/bert/lib/python3.8/site-packages/requests/sessions.py", line 724, in <listcomp>
    history = [resp for resp in gen]
  File "/opt/homebrew/anaconda3/envs/bert/lib/python3.8/site-packages/requests/sessions.py", line 265, in resolve_redirects
    resp = self.send(
  File "/opt/homebrew/anaconda3/envs/bert/lib/python3.8/site-packages/requests/sessions.py", line 703, in send
    r = adapter.send(request, **kwargs)
  File "/opt/homebrew/anaconda3/envs/bert/lib/python3.8/site-packages/requests/adapters.py", line 700, in send
    raise ConnectionError(e, request=request)
requests.exceptions.ConnectionError: HTTPSConnectionPool(host='doc-0o-1o-docs.googleusercontent.com', port=443): Max retries exceeded with url: /docs/securesc/ha0ro937gcuc7l7deffksulhg5h7mbp1/kul3p0d38qp99q7jpc8f7bmv0jhcrg4e/1740359475000/06901382624441071134/*/1IcEWOO8q8VpidPF4p51wlHPXXUnNONeZ?uuid=5a6dc7fc-074c-4f12-bc8c-729e90842e83 (Caused by NewConnectionError('<urllib3.connection.HTTPSConnection object at 0x3163d5310>: Failed to establish a new connection: [Errno 60] Operation timed out'))
[2025-02-23 20:14:20,136: INFO : main: Stage data-ingestion started]
[2025-02-23 20:14:20,137: INFO : common: yaml file: config/config.yaml loaded successfully]
[2025-02-23 20:14:20,137: INFO : common: yaml file: params.yaml loaded successfully]
[2025-02-23 20:14:20,137: INFO : common: created directory at artifacts]
[2025-02-23 20:14:20,137: INFO : common: created directory at artifacts/data_ingestion]
[2025-02-23 20:14:20,137: INFO : data_ingestion: Downloading data from https://drive.google.com/file/d/1IcEWOO8q8VpidPF4p51wlHPXXUnNONeZ/view?usp=share_link into file artifacts/data_ingestion/data.csv]
[2025-02-23 20:14:25,996: INFO : data_ingestion: Downloaded data from https://drive.google.com/file/d/1IcEWOO8q8VpidPF4p51wlHPXXUnNONeZ/view?usp=share_link into file artifacts/data_ingestion/data.csv]
[2025-02-23 20:14:25,997: INFO : main: data-ingestion completed successfully...]
[2025-02-23 20:14:25,997: INFO : main: Stage split-data started]
[2025-02-23 20:14:25,997: INFO : common: created directory at artifacts/data_split]
[2025-02-23 20:14:25,997: INFO : common: created directory at artifacts/data_split/train]
[2025-02-23 20:14:25,997: INFO : common: created directory at artifacts/data_split/test]
[2025-02-23 20:14:26,008: ERROR : main: name 'save_data' is not defined]
Traceback (most recent call last):
  File "main.py", line 22, in <module>
    data_split.split()
  File "/Users/ernestodavidserizeportela/WorkSpace/toxic-chat-clf/src/bert_toxic_chat_clf/components/data_split.py", line 27, in split
    save_data(self.config.train_data_path, train_dataset)
NameError: name 'save_data' is not defined
[2025-02-23 20:18:36,047: INFO : main: Stage data-ingestion started]
[2025-02-23 20:18:36,048: INFO : common: yaml file: config/config.yaml loaded successfully]
[2025-02-23 20:18:36,049: INFO : common: yaml file: params.yaml loaded successfully]
[2025-02-23 20:18:36,049: INFO : common: created directory at artifacts]
[2025-02-23 20:18:36,049: INFO : common: created directory at artifacts/data_ingestion]
[2025-02-23 20:18:36,049: INFO : data_ingestion: Downloading data from https://drive.google.com/file/d/1IcEWOO8q8VpidPF4p51wlHPXXUnNONeZ/view?usp=share_link into file artifacts/data_ingestion/data.csv]
[2025-02-23 20:18:53,776: INFO : data_ingestion: Downloaded data from https://drive.google.com/file/d/1IcEWOO8q8VpidPF4p51wlHPXXUnNONeZ/view?usp=share_link into file artifacts/data_ingestion/data.csv]
[2025-02-23 20:18:53,777: INFO : main: data-ingestion completed successfully...]
[2025-02-23 20:18:53,777: INFO : main: Stage split-data started]
[2025-02-23 20:18:53,777: INFO : common: created directory at artifacts/data_split]
[2025-02-23 20:18:53,777: INFO : common: created directory at artifacts/data_split/train]
[2025-02-23 20:18:53,777: INFO : common: created directory at artifacts/data_split/test]
[2025-02-23 20:18:53,798: INFO : main: split-data completed successfully...]
[2025-02-23 20:18:53,798: INFO : main: Stage setup-model started]
[2025-02-23 20:18:53,798: INFO : common: created directory at artifacts/setup_model]
[2025-02-23 20:18:58,706: INFO : main: setup-model completed successfully...]
[2025-02-23 20:18:58,706: INFO : main: Stage training started]
[2025-02-23 20:18:58,706: INFO : common: created directory at artifacts/training]
